Workbook

Sheet Sheet1
B1: TO：DAE WOO SOPHIAN CO., LTD | H1: 【PURCHASE ORDER】 | K1: 46049
K2: SVENSON
B3: Order number： | D3: 26127 | E3: AWB No. | K3: 8Floor Round-Cross Tamachi Bldg.
B4: ■Order | D4: 24 pcs | E4: ■Repair order： | H4: 66 pcs | K4: 31-19,Shiba,5-chome,MINATO-KU
B5: ■Cancel | C5: /mold | D5: 1 pcs | E5: ■Re-repair/Return | H5: 1 pcs | K5: Tokyo, JAPAN
B6: ■Order total： | D6: 25 pcs | E6: ■repair order total: | H6: 67 pcs | J6: Signature： | K6: SAORI.H
A7: no. | B7: SV.'s_x000D_ I.D. number | C7: 石膏保管 | D7: Order | E7: Customer_x000D_ number | F7: Product number | H7: Special note | I7: Request_x000D_ delivery date | J7: Rush | K7: Notices
A8: 1 | B8: 367053 | C8: ﾃﾞｰﾀ発注 364222 | D8: 製品 | E8: 00403583 | F8: 73 | G8: LC | I8: 46108 | J8: Rush(D) | K8: 石膏保管ID 364222
A9: 2 | B9: 366124 | C9: ﾃﾞｰﾀ発注 363711 | D9: 製品 | E9: 00802799 | F9: 98 | G9: LC | I9: 46108 | J9: Rush(D) | K9: 石膏保管ID 363711
A10: 3 | B10: 366412 | C10: ﾃﾞｰﾀ発注 362740 | D10: 製品 | E10: 01906601 | F10: 68 | G10: LC | I10: 46108 | J10: Rush(D) | K10: 石膏保管ID 362740
A11: 4 | B11: 367051 | C11: ﾃﾞｰﾀ発注 359794 | D11: 製品 | E11: 00401295 | F11: 102 | G11: L | I11: 46108 | J11: Rush(D) | K11: 石膏保管ID 359794
A12: 5 | B12: 366957 | C12: ﾃﾞｰﾀ発注 357986 | D12: 製品 | E12: 01405044 | F12: 56 | G12: LC | I12: 46108 | J12: Rush(D) | K12: 石膏保管ID 357986
A13: 6 | B13: 366240 | C13: ﾃﾞｰﾀ発注 357868 | D13: 製品 | E13: 00901143 | F13: 99 | G13: R | I13: 46108 | J13: Rush(D) | K13: 石膏保管ID 357868
A14: 7 | B14: 366334 | C14: ﾃﾞｰﾀ発注 357183 | D14: 製品 | E14: 01001418 | F14: 128 | G14: R | I14: 46108 | J14: Rush(D) | K14: 石膏保管ID 357183
A15: 8 | B15: 366261 | C15: ﾃﾞｰﾀ発注 354872 | D15: 製品 | E15: 00206266 | F15: 86 | G15: R | I15: 46108 | J15: Rush(D) | K15: 石膏保管ID 354872
A16: 9 | B16: 366495 | C16: ﾃﾞｰﾀ発注 354847 | D16: 製品 | E16: 01400577 | F16: 117 | G16: R | I16: 46108 | J16: Rush(D) | K16: 石膏保管ID 354847
A17: 10 | B17: 366427 | C17: ﾃﾞｰﾀ発注 352764 | D17: 製品 | E17: 00102299 | F17: 77 | G17: LC | I17: 46108 | J17: Rush(D) | K17: 石膏保管ID 352764
A18: 11 | B18: 366643 | C18: ﾃﾞｰﾀ発注 351918 | D18: 製品 | E18: 00202542 | F18: 95 | G18: R | I18: 46108 | J18: Rush(D) | K18: 石膏保管ID 351918
A19: 12 | B19: 366205 | C19: ﾃﾞｰﾀ発注 349832 | D19: 製品 | E19: 01003411 | F19: 79 | G19: LC | I19: 46108 | J19: Rush(D) | K19: 石膏保管ID 349832
... A71: 64 | B71: 366767 | C71: ﾃﾞｰﾀ発注 244150 | D71: 製品 | E71: 00403042 | F71: 69 | G71: LM | I71: 46108 | J71: *Rush | K71: 石膏保管ID 244150
A73: 1 | B73: 366142 | C73: 石膏保管 | D73: 製品 | E73: 04000001 | F73: 90 | G73: L | I73: 46108
A74: 2 | B74: 366191 | C74: 石膏保管 | D74: 製品 | E74: 01702493 | F74: 73 | G74: LC | I74: 46115
A75: 3 | B75: 366309 | C75: 石膏保管 | D75: 製品 | E75: 00200928 | F75: 82 | G75: L | I75: 46115
A76: 4 | B76: 366397 | C76: 石膏保管 | D76: 製品 | E76: 00302172 | F76: 84 | G76: R | I76: 46115
A77: 5 | B77: 366446 | C77: 石膏保管 | D77: 製品 | E77: 02500036 | F77: 91 | G77: LC | I77: 46115
A78: 6 | B78: 366504 | C78: 石膏保管 | D78: 製品 | E78: 00205606 | F78: 67 | G78: L | I78: 46115
A79: 7 | B79: 366513 | C79: 石膏保管 | D79: 製品 | E79: 01001980 | F79: 99 | G79: LC | I79: 46115
A80: 8 | B80: 366601 | C80: 石膏保管 | D80: 製品 | E80: 01002422 | F80: 70 | G80: LC | I80: 46115
A81: 9 | B81: 366608 | C81: 石膏保管 | D81: 製品 | E81: 00403703 | F81: 65 | G81: LC | I81: 46115
A82: 10 | B82: 366612 | C82: 石膏保管 | D82: 製品 | E82: 00102252 | F82: 114 | G82: L | I82: 46115
A83: 11 | B83: 366660 | C83: 石膏保管 | D83: 製品 | E83: 01501059 | F83: 99 | G83: L | I83: 46115
A84: 12 | B84: 366697 | C84: 石膏保管 | D84: 製品 | E84: 01003921 | F84: 56 | G84: L | I84: 46115
... A86: 14 | B86: 366809 | C86: 石膏保管 | D86: 製品 | E86: 01905103 | F86: 72 | G86: L | I86: 46115
A87: 15 | B87: 366899 | C87: 石膏保管 | D87: 製品 | E87: 00301715 | F87: 120 | G87: LC | I87: 46115 | J87: *Rush
A88: 16 | B88: 366908 | C88: 石膏保管 | D88: 製品 | E88: 00206082 | F88: 65 | G88: L | I88: 46115
A89: 17 | B89: 366873 | C89: 石膏保管 | D89: 製品 | E89: 01304304 | F89: 69 | G89: L | I89: 46080 | J89: Rush
A90: 18 | B90: 365971 | D90: 製品 | E90: 00201835 | F90: 109 | G90: LC | I90: 46115
A91: 19 | B91: 366245 | D91: 製品 | E91: 00206969 | F91: 66 | G91: LC | I91: 46115
A92: 20 | B92: 366331 | D92: 製品 | E92: 05200834 | F92: 54 | G92: L | I92: 46115
A93: 21 | B93: 366344 | D93: 製品 | E93: 01602990 | F93: 66 | G93: L | I93: 46115
...

Sheet Sheet2
A1: 発注ID | B1: 工場出荷日 | C1: 使用する石膏ID
A2: =Sheet1!B8 -> 367053 | B2: =Sheet1!I8 -> 46108 | C2: =Sheet1!K8 -> 石膏保管ID 364222
A3: =Sheet1!B9 -> 366124 | B3: =Sheet1!I9 -> 46108 | C3: =Sheet1!K9 -> 石膏保管ID 363711
A4: =Sheet1!B10 -> 366412 | B4: =Sheet1!I10 -> 46108 | C4: =Sheet1!K10 -> 石膏保管ID 362740
A5: =Sheet1!B11 -> 367051 | B5: =Sheet1!I11 -> 46108 | C5: =Sheet1!K11 -> 石膏保管ID 359794
A6: =Sheet1!B12 -> 366957 | B6: =Sheet1!I12 -> 46108 | C6: =Sheet1!K12 -> 石膏保管ID 357986
A7: =Sheet1!B13 -> 366240 | B7: =Sheet1!I13 -> 46108 | C7: =Sheet1!K13 -> 石膏保管ID 357868
A8: =Sheet1!B14 -> 366334 | B8: =Sheet1!I14 -> 46108 | C8: =Sheet1!K14 -> 石膏保管ID 357183
A9: =Sheet1!B15 -> 366261 | B9: =Sheet1!I15 -> 46108 | C9: =Sheet1!K15 -> 石膏保管ID 354872
A10: =Sheet1!B16 -> 366495 | B10: =Sheet1!I16 -> 46108 | C10: =Sheet1!K16 -> 石膏保管ID 354847
A11: =Sheet1!B17 -> 366427 | B11: =Sheet1!I17 -> 46108 | C11: =Sheet1!K17 -> 石膏保管ID 352764
A12: =Sheet1!B18 -> 366643 | B12: =Sheet1!I18 -> 46108 | C12: =Sheet1!K18 -> 石膏保管ID 351918
A13: =Sheet1!B19 -> 366205 | B13: =Sheet1!I19 -> 46108 | C13: =Sheet1!K19 -> 石膏保管ID 349832
... A65: =Sheet1!B71 -> 366767 | B65: =Sheet1!I71 -> 46108 | C65: =Sheet1!K71 -> 石膏保管ID 244150
